<?xml version="1.0" encoding="utf-8"?>
<!-- =================================================================================== -->
<!-- |    This document was autogenerated by xacro from ./robots/inmoov_head.urdf.xacro | -->
<!-- |    EDITING THIS FILE BY HAND IS NOT RECOMMENDED                                 | -->
<!-- =================================================================================== -->
<robot name="inmoov_hand">
  <!--xacro:property name="pi" value="3.1415926539"/-->
  <!-- meshlab steps taken from http://gazebosim.org/tutorials?tut=inertia -->
  <!-- assume material density is 1.0g per 1.0cm^2 -->
  <!-- ABS is 1.04g per 1.0cm^3 -->
  <!-- PLA is 1.25g per 1.0cm^3 -->
  <link name="base_link">
    <visual>
      <geometry>
        <cylinder length="0.0001" radius="0.26"/>
      </geometry>
      <origin rpy="0 0 0" xyz="0 0 0.055"/>
      <material name="invisible">
        <color rgba="0.3 0.3 0.3 0"/>
      </material>
    </visual>
  </link>
  <link name="head_base_link">
    <visual>
      <geometry>
        <mesh filename="package://inmoov_meshes/meshes/head_base.stl" scale="0.001 0.001 0.001"/>
      </geometry>
      <origin rpy="0 0 0" xyz="0 0 0"/>
      <material name="cframe">
        <color rgba="0.40 0.40 0.40 1"/>
      </material>
    </visual>
    <inertial>
      <mass value="43.50228125"/>
      <inertia ixx="0.025681996" ixy="1.829096875e-05" ixz="-0.00079066275" iyy="0.017327208" iyz="9.602263672e-06" izz="0.03535528"/>
    </inertial>
  </link>
  <link name="head_link">
    <visual>
      <geometry>
        <mesh filename="package://inmoov_meshes/meshes/head.stl" scale="0.001 0.001 0.001"/>
      </geometry>
      <origin rpy="0 0 0" xyz="0 0 0"/>
      <material name="cframe">
        <color rgba="0.40 0.40 0.40 1"/>
      </material>
    </visual>
    <inertial>
      <mass value="120.499460938"/>
      <inertia ixx="0.09250868" ixy="-0.000123085367188" ixz="-0.0078627105" iyy="0.150815008" iyz="0.0002850305625" izz="0.201933552"/>
    </inertial>
  </link>
  <link name="jaw_link">
    <visual>
      <geometry>
        <mesh filename="package://inmoov_meshes/meshes/jaw.stl" scale="0.001 0.001 0.001"/>
      </geometry>
      <origin rpy="0 0 0" xyz="0 0 0"/>
      <material name="ccover">
        <color rgba="0.75 0.75 0.75 1.0"/>
      </material>
    </visual>
    <inertial>
      <mass value="58.767261719"/>
      <inertia ixx="0.147272256" ixy="7.553278125e-05" ixz="0.055060208" iyy="0.134112088" iyz="-1.2159836914e-05" izz="0.156998304"/>
    </inertial>
  </link>
  <link name="skull_link">
    <visual>
      <geometry>
        <mesh filename="package://inmoov_meshes/meshes/skull.stl" scale="0.001 0.001 0.001"/>
      </geometry>
      <origin rpy="0 0 0" xyz="0 0 0"/>
      <material name="ccover">
        <color rgba="0.75 0.75 0.75 1.0"/>
      </material>
    </visual>
    <inertial>
      <mass value="422.3130625"/>
      <inertia ixx="1.82323712" ixy="0.006736614" ixz="0.115768256" iyy="2.48802176" iyz="-0.0004186136875" izz="2.440409856"/>
    </inertial>
  </link>
  <link name="left_ear_link">
    <visual>
      <geometry>
        <mesh filename="package://inmoov_meshes/meshes/earleftv1.stl" scale="0.001 0.001 0.001"/>
      </geometry>
      <origin rpy="0 0 0" xyz="0 0 0"/>
      <material name="cframe">
        <color rgba="0.40 0.40 0.40 1"/>
      </material>
    </visual>
    <inertial>
      <mass value="85.197960938"/>
      <inertia ixx="0.04423034" ixy="-0.001262894" ixz="0.005220882" iyy="0.08046712" iyz="-0.00048412846875" izz="0.04075106"/>
    </inertial>
  </link>
  <link name="right_ear_link">
    <visual>
      <geometry>
        <mesh filename="package://inmoov_meshes/meshes/earrightv1.stl" scale="0.001 0.001 0.001"/>
      </geometry>
      <origin rpy="0 0 0" xyz="0 0 0"/>
      <material name="cframe">
        <color rgba="0.40 0.40 0.40 1"/>
      </material>
    </visual>
    <inertial>
      <mass value="85.17540625"/>
      <inertia ixx="0.044218692" ixy="0.00126241425" ixz="0.0052192235" iyy="0.080448136" iyz="0.00048353196875" izz="0.040740816"/>
    </inertial>
  </link>
  <joint name="head_pan_joint" type="revolute">
    <axis xyz="0 0 1"/>
    <limit effort="1000.0" lower="-1.74532925199" upper="1.57079632679" velocity="0.0"/>
    <origin rpy="0 0 0" xyz="0 0 0.0245"/>
    <parent link="head_base_link"/>
    <child link="head_link"/>
  </joint>
  <joint name="jaw_joint" type="revolute">
    <axis xyz="0 1 0"/>
    <limit effort="1000.0" lower="0.0" upper="0.0872664625997" velocity="0.0"/>
    <origin rpy="0 0.09 0" xyz="0.0375 0.0005 0.0437"/>
    <parent link="head_link"/>
    <child link="jaw_link"/>
  </joint>
  <joint name="skull_joint" type="fixed">
    <origin rpy="0 0 0" xyz="0.044 0 -0.0245"/>
    <parent link="head_link"/>
    <child link="skull_link"/>
  </joint>
  <joint name="left_ear_joint" type="fixed">
    <origin rpy="0 0 0" xyz="0.035 0.056 0.0437"/>
    <parent link="head_link"/>
    <child link="left_ear_link"/>
  </joint>
  <joint name="right_ear_joint" type="fixed">
    <origin rpy="0 0 0" xyz="0.035 -0.056 0.0437"/>
    <parent link="head_link"/>
    <child link="right_ear_link"/>
  </joint>
  <link name="face_link">
    <visual>
      <geometry>
        <mesh filename="package://inmoov_meshes/meshes/face.stl" scale="0.001 0.001 0.001"/>
      </geometry>
      <origin rpy="0 0 0" xyz="0 0 0"/>
      <material name="ccover">
        <color rgba="0.75 0.75 0.75 1.0"/>
      </material>
    </visual>
    <inertial>
      <mass value="46.55903125"/>
      <inertia ixx="0.060878272" ixy="6.9925132812e-05" ixz="0.00126951125" iyy="0.01978544" iyz="1.37124939e-06" izz="0.051128208"/>
    </inertial>
  </link>
  <joint name="eyes_tilt_joint" type="revolute">
    <axis xyz="0 1 0"/>
    <limit effort="1000.0" lower="0.261799387799" upper="-0.261799387799" velocity="0.0"/>
    <origin rpy="0 0 0" xyz="0 0 0"/>
    <parent link="face_link"/>
    <child link="eyesupport_link"/>
  </joint>
  <link name="eyesupport_link">
    <visual>
      <geometry>
        <mesh filename="package://inmoov_meshes/meshes/eyesupport.stl" scale="0.001 0.001 0.001"/>
      </geometry>
      <origin rpy="0 0 0" xyz="0 0 0"/>
      <material name="cframe">
        <color rgba="0.40 0.40 0.40 1"/>
      </material>
    </visual>
    <inertial>
      <mass value="27.550294922"/>
      <inertia ixx="0.02063259" ixy="0.0002853024375" ixz="-0.001400304" iyy="0.016763521" iyz="0.00183966425" izz="0.006981697"/>
    </inertial>
  </link>
  <link name="r_eyesupport_link">
    <visual>
      <geometry>
        <mesh filename="package://inmoov_meshes/meshes/r_eyesupport.stl" scale="0.001 0.001 0.001"/>
      </geometry>
      <origin rpy="0 0 0" xyz="0 0 0"/>
      <material name="cframe">
        <color rgba="0.40 0.40 0.40 1"/>
      </material>
    </visual>
    <inertial>
      <mass value="11.370105469"/>
      <inertia ixx="0.00243239225" ixy="6.936413574e-06" ixz="-1.5166977539e-05" iyy="0.001752612875" iyz="0.0001608714375" izz="0.0008966528125"/>
    </inertial>
  </link>
  <link name="r_camera_link">
    <visual>
      <geometry>
        <mesh filename="package://inmoov_meshes/meshes/camera.stl" scale="0.001 0.001 0.001"/>
      </geometry>
      <origin rpy="0 0 0" xyz="0 0 0"/>
      <material name="ccamera">
        <color rgba="0.1 0.1 0.1 1"/>
      </material>
    </visual>
    <inertial>
      <mass value="2.466067627"/>
      <inertia ixx="0.000240846265625" ixy="-6.7754071e-07" ixz="-4.657491211e-06" iyy="7.5434351562e-05" iyz="-3.045460449e-06" izz="0.000181402265625"/>
    </inertial>
  </link>
  <link name="r_eye_link">
    <visual>
      <geometry>
        <mesh filename="package://inmoov_meshes/meshes/eye.stl" scale="0.001 0.001 0.001"/>
      </geometry>
      <origin rpy="0 0 0" xyz="0 0 0"/>
      <material name="ceyeball">
        <color rgba="0.7 0.7 0.7 1"/>
      </material>
    </visual>
    <inertial>
      <mass value="4.659753906"/>
      <inertia ixx="0.0009137171875" ixy="2.418e-12" ixz="2.11749e-10" iyy="0.0004795756875" iyz="-3.262e-12" izz="0.0004755305"/>
    </inertial>
  </link>
  <link name="r_iris_link">
    <visual>
      <geometry>
        <mesh filename="package://inmoov_meshes/meshes/iris.stl" scale="0.001 0.001 0.001"/>
      </geometry>
      <origin rpy="0 0 0" xyz="0 0 0"/>
      <material name="ciris">
        <color rgba="0.25 0.41 0.88 1"/>
      </material>
    </visual>
    <inertial>
      <mass value="1.026836548"/>
      <inertia ixx="8.5819992188e-05" ixy="-1.07131e-10" ixz="-2.94199e-10" iyy="4.4821710938e-05" iyz="4.19771e-10" izz="4.4822714844e-05"/>
    </inertial>
  </link>
  <joint name="r_camera_joint" type="fixed">
    <origin rpy="0 0 0" xyz="-0.001 0 0"/>
    <parent link="r_eyesupport_link"/>
    <child link="r_camera_link"/>
  </joint>
  <joint name="r_eye_joint" type="fixed">
    <origin rpy="0 0 0" xyz="0.003 0 0"/>
    <parent link="r_eyesupport_link"/>
    <child link="r_eye_link"/>
  </joint>
  <joint name="r_iris_joint" type="fixed">
    <origin rpy="0 0 0" xyz="0.0061 0 0"/>
    <parent link="r_eyesupport_link"/>
    <child link="r_iris_link"/>
  </joint>
  <joint name="eyes_pan_joint" type="revolute">
    <axis xyz="0 0 1"/>
    <limit effort="1000.0" lower="-0.523598775598" upper="0.523598775598" velocity="0.0"/>
    <origin rpy="0 0 0" xyz="0 0.033 -0.0036"/>
    <parent link="eyesupport_link"/>
    <child link="r_eyesupport_link"/>
  </joint>
  <link name="l_eyesupport_link">
    <visual>
      <geometry>
        <mesh filename="package://inmoov_meshes/meshes/l_eyesupport.stl" scale="0.001 0.001 0.001"/>
      </geometry>
      <origin rpy="0 0 0" xyz="0 0 0"/>
      <material name="cframe">
        <color rgba="0.40 0.40 0.40 1"/>
      </material>
    </visual>
    <inertial>
      <mass value="11.370105469"/>
      <inertia ixx="0.00243239225" ixy="-6.936314941e-06" ixz="-1.5166963867e-05" iyy="0.00175261275" iyz="-0.0001608714375" izz="0.0008966526875"/>
    </inertial>
  </link>
  <link name="l_camera_link">
    <visual>
      <geometry>
        <mesh filename="package://inmoov_meshes/meshes/camera.stl" scale="0.001 0.001 0.001"/>
      </geometry>
      <origin rpy="0 0 0" xyz="0 0 0"/>
      <material name="ccamera">
        <color rgba="0.1 0.1 0.1 1"/>
      </material>
    </visual>
    <inertial>
      <mass value="2.466067627"/>
      <inertia ixx="0.000240846265625" ixy="-6.7754071e-07" ixz="-4.657491211e-06" iyy="7.5434351562e-05" iyz="-3.045460449e-06" izz="0.000181402265625"/>
    </inertial>
  </link>
  <link name="l_eye_link">
    <visual>
      <geometry>
        <mesh filename="package://inmoov_meshes/meshes/eye.stl" scale="0.001 0.001 0.001"/>
      </geometry>
      <origin rpy="0 0 0" xyz="0 0 0"/>
      <material name="ceyeball">
        <color rgba="0.7 0.7 0.7 1"/>
      </material>
    </visual>
    <inertial>
      <mass value="4.659753906"/>
      <inertia ixx="0.0009137171875" ixy="2.418e-12" ixz="2.11749e-10" iyy="0.0004795756875" iyz="-3.262e-12" izz="0.0004755305"/>
    </inertial>
  </link>
  <link name="l_iris_link">
    <visual>
      <geometry>
        <mesh filename="package://inmoov_meshes/meshes/iris.stl" scale="0.001 0.001 0.001"/>
      </geometry>
      <origin rpy="0 0 0" xyz="0 0 0"/>
      <material name="ciris">
        <color rgba="0.25 0.41 0.88 1"/>
      </material>
    </visual>
    <inertial>
      <mass value="1.026836548"/>
      <inertia ixx="8.5819992188e-05" ixy="-1.07131e-10" ixz="-2.94199e-10" iyy="4.4821710938e-05" iyz="4.19771e-10" izz="4.4822714844e-05"/>
    </inertial>
  </link>
  <joint name="l_camera_joint" type="fixed">
    <origin rpy="0 0 0" xyz="-0.001 0 0"/>
    <parent link="l_eyesupport_link"/>
    <child link="l_camera_link"/>
  </joint>
  <joint name="l_eye_joint" type="fixed">
    <origin rpy="0 0 0" xyz="0.003 0 0"/>
    <parent link="l_eyesupport_link"/>
    <child link="l_eye_link"/>
  </joint>
  <joint name="l_iris_joint" type="fixed">
    <origin rpy="0 0 0" xyz="0.0061 0 0"/>
    <parent link="l_eyesupport_link"/>
    <child link="l_iris_link"/>
  </joint>
  <joint name="l_eye_pan_joint" type="revolute">
    <axis xyz="0 0 1"/>
    <limit effort="1000.0" lower="-0.523598775598" upper="0.523598775598" velocity="0.0"/>
    <mimic joint="eyes_pan_joint" multiplier="1" offset="0"/>
    <origin rpy="0 0 0" xyz="0 -0.033 -0.0036"/>
    <parent link="eyesupport_link"/>
    <child link="l_eyesupport_link"/>
  </joint>
  <joint name="base_to_base" type="revolute">
    <axis xyz="0 0 1"/>
    <limit effort="1000.0" lower="-3.14" upper="0" velocity="0.5"/>
    <origin rpy="0 0 0" xyz="0 0 0"/>
    <parent link="base_link"/>
    <child link="head_base_link"/>
  </joint>
  <joint name="face" type="fixed">
    <origin rpy="0 0 0" xyz="0 0.0637 0.079"/>
    <parent link="skull_link"/>
    <child link="face_link"/>
  </joint>
</robot>

